<robot name="simple_robot">

  <link name="root_link">
    <inertial>
      <mass value="1.0"/>
      <inertia ixx="0.16667" ixy="0.0" ixz="0.0" iyy="0.16667" iyz="0.0" izz="0.33333"/>
    </inertial>
    <visual>
      <geometry>
        <cylinder radius="0.1" length="0.4"/>
      </geometry>
    </visual>
    <collision>
      <geometry>
        <cylinder radius="0.1" length="0.4"/>
      </geometry>
    </collision>
  </link>

  <link name="link_1">
    <inertial>
      <mass value="1.0"/>
      <inertia ixx="0.16667" ixy="0.0" ixz="0.0" iyy="0.16667" iyz="0.0" izz="0.33333"/>
    </inertial>
    <visual>
      <geometry>
        <cylinder radius="0.1" length="0.4"/>
      </geometry>
    </visual>
    <collision>
      <geometry>
        <cylinder radius="0.1" length="0.4"/>
      </geometry>
    </collision>
  </link>

  <link name="link_2">
    <inertial>
      <mass value="1.0"/>
      <inertia ixx="0.16667" ixy="0.0" ixz="0.0" iyy="0.16667" iyz="0.0" izz="0.33333"/>
    </inertial>
    <visual>
      <geometry>
        <cylinder radius="0.1" length="0.4"/>
      </geometry>
    </visual>
    <collision>
      <geometry>
        <cylinder radius="0.1" length="0.4"/>
      </geometry>
    </collision>
  </link>

  <joint name="joint_1" type="revolute">
    <origin xyz="0 0 0.4" rpy="0 0 0"/>
    <parent link="root_link"/>
    <child link="link_1"/>
    <axis xyz="0 1 0"/>
    <limit effort="50000" lower="-1.66" upper="0.17" velocity="50000"/>
  </joint>

  <joint name="joint_2" type="revolute">
    <origin xyz="0 0 0.4" rpy="0 0 0"/>
    <parent link="link_1"/>
    <child link="link_2"/>
    <axis xyz="0 1 0"/>
    <limit effort="50000" lower="-1.66" upper="0.17" velocity="50000"/>
  </joint>

</robot>
